Workbook
Name _xlfn.BAHTTEXT: #NAME?
Name LIN_DISTR_ELECT.: '[1]PRES 1'!#REF!
Name SUBEST_ELECTR: '[1]PRES 1'!#REF!
Name CAJA_DE_CAPTACION: #REF!
Name SERIES: #REF!

Sheet DATOS
C1: ESTUDIO FINANCIERO
C3: DATOS ADICIONALES
C5: Inflación | D5: 0.09 | E5: Anual
C6: Incremento salarial | D6: 0.12 | E6: Anual
C7: Incremento volumen | D7: 0.03 | E7: cada 3 meses durante el primer año
C8: Incremento precio unitario de venta | D8: 0.09 | E8: A partir del segundo semestre del primer año y durante los sig años
C10: Depreciación en línea recta | E10: LISR
C12: Amortización de la deuda de acuerdo a la
C13: dependencia que otorgará el financiamiento

Sheet ESTRUCTURA FINANCIERA
A1: ESTUDIO FINANCIERO
A3: ESTRUCTURA FINANCIERA
A5: PROYECTO: EXPANSIÓN DE MICEL DISTRIBUIDOR AUTORIZADO TELCEL
A6: SOCIEDAD: MICEL DISTRIBUIDOR AUTORIZADO TELCEL- VMD
A7: BENEFICIARIOS: VICTOR DANIEL MARINI DEBERNARDI
A9: DESGLOSE DE INVERSION PARA UN AÑO
A10: CONCEPTO | B10: UNIDAD DE | C10: CANTIDAD | D10: PRECIO | E10: COSTO | F10: APORTACION
B11: MEDIDA | D11: UNITARIO | E11: TOTAL | F11: DEPENDENCIA | G11: GRUPO
A12: CAPITAL DE TRABAJO
A13: Equipos (celulares, modems, tablets) | B13: PZAS | C13: 50 | D13: 3400 | E13: =C13*D13 -> 170000 | F13: 170000
A14: Accesorios | B14: PZAS | C14: 250 | D14: 140 | E14: =C14*D14 -> 35000 | F14: 35000
A15: Saldo en el portal | B15: SERVICIO | C15: 1 | D15: 10000 | E15: =C15*D15 -> 10000 | F15: 10000
A16: Papelería y Limpieza | B16: PZAS | C16: 15 | D16: 33.333333 | E16: =C16*D16 -> 500 | G16: 500
A17: Uniformes | B17: PZAS | C17: 6 | D17: 200 | E17: =C17*D17 -> 1200 | G17: 1200
A19: INVERSION FIJA
A20: Pintura y trabajos de tablaroca | B20: SERVICIO | C20: 1 | D20: 5000 | E20: =C20*D20 -> 5000 | F20: 5000
A21: Equipo de computo | B21: UNIDAD | C21: 1 | D21: 8000 | E21: =C21*D21 -> 8000 | F21: 8000
A22: Modificaciones eléctricas | B22: PZAS | C22: 1 | D22: 1500 | E22: =C22*D22 -> 1500 | F22: 1500
A23: Exhibipaneles | B23: PZAS | C23: 2 | D23: 1000 | E23: =C23*D23 -> 2000 | F23: 2000
A24: Ganchos para exhibipaneles y bases de teléfonos | B24: PZAS | C24: 100 | D24: 15 | E24: =C24*D24 -> 1500 | F24: 1500
A25: Mobiliario (Vitrinas, sillas y caja) | B25: PZAS | C25: 4 | D25: 5000 | E25: =C25*D25 -> 20000 | F25: 20000
A26: Anuncio luminoso | B26: PZAS | C26: 1 | D26: 12000 | E26: =C26*D26 -> 12000 | F26: 12000
A27: Pantalla | B27: PZAS | C27: 1 | D27: 5000 | E27: =C27*D27 -> 5000 | F27: 5000
A28: Depósito de Renta y Renta adelantada del local | B28: UNIDAD | C28: 2 | D28: 6000 | E28: =C28*D28 -> 12000 | G28: 12000
A29: Instalación de Servicios | B29: UNIDAD | C29: 1 | D29: 2000 | E29: =C29*D29 -> 2000 | F29: 2000
A30: Licencia del sistema de Ventas | B30: UNIDAD | C30: 1 | D30: 1000 | E30: =C30*D30 -> 1000 | G30: 1000
A31: Cámaras de seguridad | B31: PZAS | C31: 4 | D31: 1500 | E31: =C31*D31 -> 6000 | F31: 6000
A32: Regulador de voltaje | B32: PZAS | C32: 1 | D32: 1000 | E32: =C32*D32 -> 1000 | G32: 1000
A35: Subtotal | E35: =SUM(E13:E34) -> 293700 | F35: =SUM(F13:F22) -> 229500 | G35: =SUM(G13:G34) -> 15700
A36: INVERSIÓN DIFERIDA
A37: Capacitación | B37: SERVICIO | C37: 2 | D37: 1000 | E37: =C37*D37 -> 2000 | F37: 2000
A53: TOTAL | E53: =+E52+E42+E35 -> 293700 | F53: =+F52+F42+F35 -> 229500 | G53: =+G52+G35 -> 15700
A54: PORCENTAJE | E54: =+E53/E53 -> 1 | F54: =+F53/E53 -> 0.7814096 | G54: 0.55
A57: NOTAS: LA ESTRUCTURA FINANCIERA ESTÁ DESGLOSADA PARA LA APERTURA DE 1 NUEVA SUCURSAL. LA VISIÓN DEL PROYECTO ES ABRIR 9, POR LO TANTO SE MUESTRA A CONTINUACIÓN LOS MONTOS TOTALES POR 9 SUCURSALES.
B58: 1 SUCURSAL | E58: 9 SUCURSALES
A59: CONCEPTO | B59: DEPENDENCIA | C59: GRUPO | D59: TOTAL | E59: DEPENDENCIA | F59: GRUPO | G59: TOTAL
A61: Cap. Trabajo | B61: 215000 | C61: 1700 | D61: =B61+C61 -> 216700 | E61: =B61*9 -> 1935000 | F61: =C61*9 -> 15300 | G61: =E61+F61 -> 1950300
A62: Inv. Fija | B62: 63000 | C62: 14000 | D62: =B62+C62 -> 77000 | E62: =B62*9 -> 567000 | F62: =C62*9 -> 126000 | G62: =E62+F62 -> 693000
A63: Inv. Diferida | B63: 2000 | D63: =B63+C63 -> 2000 | E63: =B63*9 -> 18000 | F63: =C63*9 -> 0 | G63: =E63+F63 -> 18000
A64: Total | B64: =B61+B62+B63 -> 280000 | C64: =C61+C62 -> 15700 | D64: =SUM(D61:D63) -> 295700 | E64: =B64*9 -> 2520000 | F64: =C64*9 -> 141300 | G64: =G61+G62+G63 -> 2661300
...

Sheet CUADRO DE EGRESOS E INGRESOS
A1: ESTRUCTURA DE INGRESOS Y EGERESOS
A3: SITUACION FINANCIERA ACTUAL Y PROYECTADA
A5: PROYECTO: EXPANSIÓN DE MICEL DISTRIBUIDOR AUTORIZADO TELCEL
A6: SOCIEDAD: MICEL DISTRIBUIDOR AUTORIZADO TELCEL- VMD
A7: BENEFICIARIOS: VICTOR DANIEL MARINI DEBERNARDI
B9: FLUJO DE I N G R E S O S Y E G R E S O S
A10: PRIMER AÑO DE INVERSIÓN
A11: C O N C E P T O | C11: 1 MES | D11: 2 MES | E11: 3 MES | F11: 4 MES | G11: 5 MES | H11: 6 MES | I11: 7 MES | J11: 8 MES | K11: 9 MES | L11: 10 MES | M11: 11 MES | N11: 12 MES | O11: TOTAL
A12: INGRESOS POR PRODUCTOS | C12: 92169.19 | D12: =C12*0.01+C12 -> 93090.882 | E12: =D12*0.01+D12 -> 94021.791 | F12: =E12*0.01+E12 -> 94962.009 | G12: =F12*0.01+F12 -> 95911.629 | H12: =G12*0.01+G12 -> 96870.745 | I12: =H12*0.01+H12 -> 97839.452 | J12: =I12*0.01+I12 -> 98817.847 | K12: =J12*0.01+J12 -> 99806.025 | ... N12: =M12*0.01+M12 -> 102830.25 | O12: =SUM(B12:N12) -> 1168936
A13: INGRESOS POR SERVICIOS | C13: 18195.79 | D13: =C13*0.01+C13 -> 18377.748 | E13: =D13*0.01+D13 -> 18561.525 | F13: =E13*0.01+E13 -> 18747.141 | G13: =F13*0.01+F13 -> 18934.612 | H13: =G13*0.01+G13 -> 19123.958 | I13: =H13*0.01+H13 -> 19315.198 | J13: =I13*0.01+I13 -> 19508.35 | K13: =J13*0.01+J13 -> 19703.433 | ... N13: =M13*0.01+M13 -> 20300.467 | O13: =SUM(B13:N13) -> 230768.16
A14: INGRESOS POR COMISIONES | C14: 300000 | D14: 300000 | E14: 300000 | F14: 300000 | G14: 300000 | H14: 300000 | I14: 300000 | J14: 300000 | K14: 300000 | L14: 300000 | M14: 300000 | N14: 300000 | O14: =SUM(B14:N14) -> 3600000
A15: TOTAL DE INGRESOS | C15: =SUM(C12:C14) -> 410364.98 | D15: =SUM(D12:D14) -> 411468.63 | E15: =SUM(E12:E14) -> 412583.32 | F15: =SUM(F12:F14) -> 413709.15 | G15: =SUM(G12:G14) -> 414846.24 | H15: =SUM(H12:H14) -> 415994.7 | I15: =SUM(I12:I14) -> 417154.65 | J15: =SUM(J12:J14) -> 418326.2 | ... N15: =SUM(N12:N14) -> 423130.71 | O15: =SUM(C15:N15) -> 4999704.2
F16: aumenta 3 | J16: aumento 3% | K16: 0 | L16: 0 | M16: =+M13*A16 -> 0 | O16: =+J16 -> aumento 3%
A17: EGRESOS
A18: VARIABLE | C18: ='M. DE CALCULO DE COSTOS VARIABL'!E15 -> 215000 | D18: =C18 -> 215000 | E18: =D18 -> 215000 | F18: =E18 -> 215000 | G18: =F18 -> 215000 | H18: =G18 -> 215000 | I18: =H18 -> 215000 | J18: =I18 -> 215000 | K18: =J18 -> 215000 | ... N18: =M18 -> 215000 | O18: =SUM(B18:N18) -> 2580000
A19: FIJOS | C19: ='M. DE CALCULO DE GASTOS FIJOS'!F36 -> 40521.94 | D19: ='M. DE CALCULO DE GASTOS FIJOS'!G36 -> 33521.94 | E19: ='M. DE CALCULO DE GASTOS FIJOS'!H36 -> 33521.94 | F19: ='M. DE CALCULO DE GASTOS FIJOS'!I36 -> 33521.94 | G19: ='M. DE CALCULO DE GASTOS FIJOS'!J36 -> 33521.94 | H19: ='M. DE CALCULO DE GASTOS FIJOS'!K36 -> 33521.94 | I19: ='M. DE CALCULO DE GASTOS FIJOS'!L36 -> 33521.94 | J19: ='M. DE CALCULO DE GASTOS FIJOS'!M36 -> 33521.94 | ... N19: ='M. DE CALCULO DE GASTOS FIJOS'!Q36 -> 33521.94 | O19: =SUM(B19:N19) -> 409263.28
A20: SALDO | C20: =C15-C18-C19 -> 154843.04 | D20: =D15-D18-D19 -> 162946.69 | E20: =E15-E18-E19 -> 164061.38 | F20: =F15-F18-F19 -> 165187.21 | G20: =G15-G18-G19 -> 166324.3 | H20: =H15-H18-H19 -> 167472.76 | I20: =I15-I18-I19 -> 168632.71 | J20: =J15-J18-J19 -> 169804.26 | ... N20: =N15-N18-N19 -> 174608.77 | O20: =SUM(B20:N20) -> 2010440.9 | P20: 9 sucursales
A21: SALDO ACUMULADO | C21: =+C20 -> 154843.04 | D21: =+D20+C21 -> 317789.73 | E21: =+E20+D21 -> 481851.11 | F21: =+F20+E21 -> 647038.32 | G21: =+G20+F21 -> 813362.62 | H21: =+H20+G21 -> 980835.38 | I21: =+I20+H21 -> 1149468.1 | J21: =+J20+I21 -> 1319272.3 | K21: =+K20+J21 -> 1490259.9 | ... N21: =+N20+M21 -> 2010440.9 | O21: =+N21 -> 2010440.9 | P21: =O21*9 -> 18093968
A25: PROYECCION FINANCIERA ANUAL
A27: SEGUNDO AÑO DE INVERSIÓN
A28: C O N C E P T O | C28: 1 MES | D28: 2 MES | E28: 3 MES | F28: 4 MES | G28: 5 MES | H28: 6 MES | I28: 7 MES | J28: 8 MES | K28: 9 MES | L28: 10 MES | M28: 11 MES | N28: 12 MES | O28: TOTAL
A29: INGRESOS POR PRODUCTOS | C29: =C12*1.09 -> 100464.42 | D29: =C29 -> 100464.42 | E29: =D29 -> 100464.42 | F29: =E29 -> 100464.42 | G29: =F29 -> 100464.42 | H29: =G29 -> 100464.42 | I29: =H29 -> 100464.42 | J29: =I29 -> 100464.42 | K29: =J29 -> 100464.42 | ... N29: =M29 -> 100464.42 | O29: =SUM(C29:N29) -> 1205573
A30: INGRESOS POR SERVICIOS | C30: =C13*1.09 -> 19833.411 | D30: =C30 -> 19833.411 | E30: =D30 -> 19833.411 | F30: =E30 -> 19833.411 | G30: =F30 -> 19833.411 | H30: =G30 -> 19833.411 | I30: =H30 -> 19833.411 | J30: =I30 -> 19833.411 | K30: =J30 -> 19833.411 | ... N30: =M30 -> 19833.411 | O30: =SUM(C30:N30) -> 238000.93
A31: INGRESOS POR COMISIONES | C31: =C14*1.09 -> 327000 | D31: =D14*1.09 -> 327000 | E31: =E14*1.09 -> 327000 | F31: =F14*1.09 -> 327000 | G31: =G14*1.09 -> 327000 | H31: =H14*1.09 -> 327000 | I31: =I14*1.09 -> 327000 | J31: =J14*1.09 -> 327000 | ... N31: =N14*1.09 -> 327000 | O31: =SUM(B31:N31) -> 3924000
A32: TOTAL DE INGRESOS | C32: =SUM(C29:C31) -> 447297.83 | D32: =C32 -> 447297.83 | E32: =D32 -> 447297.83 | F32: =E32 -> 447297.83 | G32: =F32 -> 447297.83 | H32: =G32 -> 447297.83 | I32: =H32 -> 447297.83 | J32: =I32 -> 447297.83 | K32: =J32 -> 447297.83 | ... N32: =M32 -> 447297.83 | O32: =SUM(C32:N32) -> 5367573.9
K33: 0 | L33: 0 | M33: =+M30*A33 -> 0 | O33: =SUM(C33:N33) -> 0
A34: EGRESOS | O34: =SUM(C34:N34) -> 0
A35: VARIABLE | C35: =C18*1.09 -> 234350 | D35: =D18*1.09 -> 234350 | E35: =E18*1.09 -> 234350 | F35: =F18*1.09 -> 234350 | G35: =G18*1.09 -> 234350 | H35: =H18*1.09 -> 234350 | I35: =I18*1.09 -> 234350 | J35: =J18*1.09 -> 234350 | ... N35: =N18*1.09 -> 234350 | O35: =SUM(B35:N35) -> 2812200
A36: FIJOS | C36: =D19*1.09 -> 36538.915 | D36: =E19*1.09 -> 36538.915 | E36: =F19*1.09 -> 36538.915 | F36: =G19*1.09 -> 36538.915 | G36: =H19*1.09 -> 36538.915 | H36: =I19*1.09 -> 36538.915 | I36: =J19*1.09 -> 36538.915 | J36: =K19*1.09 -> 36538.915 | ... M36: =N19*1.09 -> 36538.915 | N36: =N19*1.09 -> 36538.915 | O36: =SUM(C36:N36) -> 438466.98
A37: SALDO | C37: =C32-C35-C36 -> 176408.91 | D37: =D32-D35-D36 -> 176408.91 | E37: =E32-E35-E36 -> 176408.91 | F37: =F32-F35-F36 -> 176408.91 | G37: =G32-G35-G36 -> 176408.91 | H37: =H32-H35-H36 -> 176408.91 | I37: =I32-I35-I36 -> 176408.91 | J37: =J32-J35-J36 -> 176408.91 | ... N37: =N32-N35-N36 -> 176408.91 | O37: =SUM(C37:N37) -> 2116907 | P37: 9 sucursales
A38: SALDO ACUMULADO | C38: =+C37 -> 176408.91 | D38: =+D37+C38 -> 352817.83 | E38: =+E37+D38 -> 529226.74 | F38: =+F37+E38 -> 705635.65 | G38: =+G37+F38 -> 882044.57 | H38: =+H37+G38 -> 1058453.5 | I38: =+I37+H38 -> 1234862.4 | J38: =+J37+I38 -> 1411271.3 | K38: =+K37+J38 -> 1587680.2 | ... N38: =+N37+M38 -> 2116907 | O38: =+N38 -> 2116907 | P38: =O38*9 -> 19052163
A40: PROYECCION FINANCIERA ANUAL
A42: TERCER AÑO DE INVERSIÓN
A43: C O N C E P T O | C43: 1 MES | D43: 2 MES | E43: 3 MES | F43: 4 MES | G43: 5 MES | H43: 6 MES | I43: 7 MES | J43: 8 MES | K43: 9 MES | L43: 10 MES | M43: 11 MES | N43: 12 MES | O43: TOTAL
A44: INGRESOS POR PRODUCTOS | C44: =100464.4171*1.09 -> 109506.21 | D44: =100464.4171*1.09 -> 109506.21 | E44: =100464.4171*1.09 -> 109506.21 | F44: =100464.4171*1.09 -> 109506.21 | G44: =100464.4171*1.09 -> 109506.21 | H44: =100464.4171*1.09 -> 109506.21 | I44: =100464.4171*1.09 -> 109506.21 | J44: =100464.4171*1.09 -> 109506.21 | ... N44: =100464.4171*1.09 -> 109506.21 | O44: =SUM(C43:N44) -> 1314074.6
A45: INGRESOS POR SERVICIOS | C45: =19833.4111*1.09 -> 21618.418 | D45: =19833.4111*1.09 -> 21618.418 | E45: =19833.4111*1.09 -> 21618.418 | F45: =19833.4111*1.09 -> 21618.418 | G45: =19833.4111*1.09 -> 21618.418 | H45: =19833.4111*1.09 -> 21618.418 | I45: =19833.4111*1.09 -> 21618.418 | J45: =19833.4111*1.09 -> 21618.418 | ... N45: =19833.4111*1.09 -> 21618.418 | O45: =SUM(C44:N45) -> 1573495.6
A46: INGRESOS POR COMISIONES | C46: =C31*1.09 -> 356430 | D46: =D31*1.09 -> 356430 | E46: =E31*1.09 -> 356430 | F46: =F31*1.09 -> 356430 | G46: =G31*1.09 -> 356430 | H46: =H31*1.09 -> 356430 | I46: =I31*1.09 -> 356430 | J46: =J31*1.09 -> 356430 | ... N46: =N31*1.09 -> 356430 | O46: =SUM(B46:N46) -> 4277160
A47: TOTAL DE INGRESOS | C47: =SUM(C44:C46) -> 487554.63 | D47: =SUM(D44:D46) -> 487554.63 | E47: =SUM(E44:E46) -> 487554.63 | F47: =SUM(F44:F46) -> 487554.63 | G47: =SUM(G44:G46) -> 487554.63 | H47: =SUM(H44:H46) -> 487554.63 | I47: =SUM(I44:I46) -> 487554.63 | J47: =SUM(J44:J46) -> 487554.63 | ... N47: =SUM(N44:N46) -> 487554.63 | O47: =SUM(B47:N47) -> 5850655.6
K48: 0 | L48: 0 | M48: =+M45*A48 -> 0 | O48: =SUM(C47:N48) -> 5850655.6
A49: EGRESOS | O49: =SUM(C48:N49) -> 0
...

Sheet M. DE CALCULO DE COSTOS VARIABL
A1: ESTRUCTURA DE INGRESOS Y EGRESOS
A3: MEMORIAS DE CALCULO COSTOS VARIABLES
A5: PROYECTO: EXPANSIÓN DE MICEL DISTRIBUIDOR AUTORIZADO TELCEL
A6: SOCIEDAD: MICEL DISTRIBUIDOR AUTORIZADO TELCEL- VMD
A7: BENEFICIARIOS: VICTOR DANIEL MARINI DEBERNARDI
A8: MEMORIA DE CALCULO MATERIA PRIMA E INSUMOS PARA 1 SUCURSAL | F8: PARA 9 SUCURSALES
B9: MEDIDA | C9: CANT | D9: C.U. | E9: TOTAL | F9: TOTALES
A10: TELEFONÍA | B10: PIEZAS | C10: 50 | D10: 3400 | E10: =C10*D10 -> 170000 | F10: =E10*9 -> 1530000
A11: ACCESORIOS | B11: PIEZAS | C11: 250 | D11: 140 | E11: =C11*D11 -> 35000 | F11: =E11*9 -> 315000
A12: SALDO EN EL PORTAL | B12: SERVICIO | C12: 1 | D12: 10000 | E12: =C12*D12 -> 10000 | F12: =E12*9 -> 90000
A15: Subtotal | E15: =SUM(E10:E12) -> 215000 | F15: =E15*9 -> 1935000

Sheet M. DE CALCULO DE GASTOS FIJOS
A1: ESTRUCTURA DE INGRESOS Y EGERESOS
A3: MEMORIAS DE CALCULO GASTOS FIJOS
A5: PROYECTO: EXPANSIÓN DE MICEL DISTRIBUIDOR AUTORIZADO TELCEL
A6: SOCIEDAD: MICEL DISTRIBUIDOR AUTORIZADO TELCEL- VMD
A7: BENEFICIARIOS: VICTOR DANIEL MARINI DEBERNARDI
A8: MEMORIA DE CALCULO GASTOS DE ADMINISTRACIÓN | F8: MESES
B9: MEDIDA | C9: CANT | D9: C.U. | E9: TOTAL | F9: 1 | G9: 2 | H9: 3 | I9: 4 | J9: 5 | K9: 6 | L9: 7 | M9: 8 | N9: 9 | O9: 10 | P9: 11 | Q9: 12 | R9: TOTAL ANUAL POR 1 SUCURSAL | S9: TOTAL ANUAL POR 9 SUCURSALES
A10: GASTOS ADMINISTRATIVOS | B10: MESES | C10: 1 | D10: 2000 | E10: =C10*D10 -> 2000 | F10: 2000 | G10: 2000 | H10: 2000 | I10: 2000 | J10: 2000 | K10: 2000 | L10: 2000 | M10: 2000 | N10: 2000 | O10: 2000 | P10: 2000 | Q10: 2000 | R10: =SUM(F10:Q10) -> 24000 | S10: =R10*9 -> 216000
A15: Subtotal
A18: MEMORIA DE CALCULO GASTOS DE VENTA | F18: MESES
B19: MEDIDA | C19: CANT | D19: C.U. | E19: TOTAL | F19: 1 | G19: 2 | H19: 3 | I19: 4 | J19: 5 | K19: 6 | L19: 7 | M19: 8 | N19: 9 | O19: 10 | P19: 11 | Q19: 12 | R19: TOTAL ANUAL POR 1 SUCURSAL | S19: TOTAL ANUAL POR 9 SUCURSALES
A20: NÓMINA | B20: MONTO | C20: 2 | D20: 9054 | E20: =C20*D20 -> 18108 | F20: =E20 -> 18108 | G20: =E20 -> 18108 | H20: =G20 -> 18108 | I20: =H20 -> 18108 | J20: =H20 -> 18108 | K20: =J20 -> 18108 | L20: =K20 -> 18108 | M20: =K20 -> 18108 | N20: =M20 -> 18108 | O20: =N20 -> 18108 | P20: =N20 -> 18108 | Q20: =P20 -> 18108 | R20: =SUM(F20:Q20) -> 217296 | S20: =R20*9 -> 1955664
A21: DEPÓSITO | B21: MONTO | C21: 1 | D21: 6000 | F21: 6000 | R21: 6000
A22: RENTA DEL LOCAL | B22: MONTO | C22: 1 | D22: 6000 | F22: 6000 | G22: 6000 | H22: 6000 | I22: 6000 | J22: 6000 | K22: 6000 | L22: 6000 | M22: 6000 | N22: 6000 | O22: 6000 | P22: 6000 | Q22: 6000 | R22: =SUM(F22:Q22) -> 72000 | S22: =R22*9 -> 648000
A23: SERVICIOS (LUZ, AGUA E INTERNET) | B23: MONTO | C23: 1 | D23: 1000 | F23: 1000 | G23: 1000 | H23: 1000 | I23: 1000 | J23: 1000 | K23: 1000 | L23: 1000 | M23: 1000 | N23: 1000 | O23: 1000 | P23: 1000 | Q23: 1000 | R23: =SUM(F23:Q23) -> 12000 | S23: =R23*9 -> 108000
A24: PUBLICIDAD | B24: UNIDAD | C24: 1 | D24: 1000 | F24: 1000 | R24: 1000 | S24: =R24*9 -> 9000
A25: Subtotal | D25: =SUM(D20:D24) -> 23054 | E25: =SUM(E20:E24) -> 18108 | F25: =SUM(F20:F24) -> 32108 | G25: =SUM(G20:G24) -> 25108 | H25: =SUM(H20:H24) -> 25108 | I25: =SUM(I20:I24) -> 25108 | J25: =SUM(J20:J24) -> 25108 | K25: =SUM(K20:K24) -> 25108 | ... Q25: =SUM(Q20:Q24) -> 25108
A28: MEMORIA DE CALCULO GASTOS SOCIALES | F28: MESES
F29: 1 | G29: 2 | H29: 3 | I29: 4 | J29: 5 | K29: 6 | L29: 7 | M29: 8 | N29: 9 | O29: 10 | P29: 11 | Q29: 12
A30: ISR | B30: MONTO | C30: 2 | D30: 1110.87 | E30: =C30*D30 -> 2221.74 | F30: =E30 -> 2221.74 | G30: =E30 -> 2221.74 | H30: =G30 -> 2221.74 | I30: =H30 -> 2221.74 | J30: =H30 -> 2221.74 | K30: =J30 -> 2221.74 | L30: =K30 -> 2221.74 | M30: =K30 -> 2221.74 | N30: =M30 -> 2221.74 | O30: =N30 -> 2221.74 | P30: =N30 -> 2221.74 | Q30: =P30 -> 2221.74 | R30: =SUM(F30:Q30) -> 26660.88 | S30: =R30*9 -> 239947.92
A31: IMSS | B31: MONTO | C31: 2 | D31: 1107.74 | E31: =D31*C31 -> 2215.48 | F31: =E31 -> 2215.48 | G31: =E31 -> 2215.48 | H31: =G31 -> 2215.48 | I31: =H31 -> 2215.48 | J31: =H31 -> 2215.48 | K31: =J31 -> 2215.48 | L31: =K31 -> 2215.48 | M31: =K31 -> 2215.48 | N31: =M31 -> 2215.48 | O31: =N31 -> 2215.48 | P31: =N31 -> 2215.48 | Q31: =P31 -> 2215.48 | R31: =SUM(F31:Q31) -> 26585.76 | S31: =R31*9 -> 239271.84
A32: BONOS | B32: MONTO | C32: 2 | D32: 500 | E32: =C32*D32 -> 1000 | F32: =E32 -> 1000 | G32: =F32 -> 1000 | H32: =G32 -> 1000 | I32: =H32 -> 1000 | J32: =I32 -> 1000 | K32: =J32 -> 1000 | L32: =K32 -> 1000 | M32: =L32 -> 1000 | ... Q32: =P32 -> 1000 | R32: =SUM(F32:Q32) -> 12000 | S32: =R32*9 -> 108000
A33: PRIMA VACACIONAL | B33: MONTO | C33: 2 | D33: 75.45 | E33: =D33*C33 -> 150.9 | F33: =E33 -> 150.9 | G33: =F33 -> 150.9 | H33: =G33 -> 150.9 | I33: =H33 -> 150.9 | J33: =I33 -> 150.9 | K33: =J33 -> 150.9 | L33: =K33 -> 150.9 | M33: =L33 -> 150.9 | ... Q33: =P33 -> 150.9 | R33: =SUM(F33:Q33) -> 1810.8 | S33: =R33*9 -> 16297.2
A34: AGUINALDO | B34: MONTO | C34: 2 | D34: 412.91 | E34: =C34*D34 -> 825.82 | F34: =E34 -> 825.82 | G34: =F34 -> 825.82 | H34: =G34 -> 825.82 | I34: =H34 -> 825.82 | J34: =I34 -> 825.82 | K34: =J34 -> 825.82 | L34: =K34 -> 825.82 | M34: =L34 -> 825.82 | ... Q34: =P34 -> 825.82 | R34: =SUM(F34:Q34) -> 9909.84 | S34: =R34*9 -> 89188.56
A35: Subtotal | D35: =SUM(D30:D34) -> 3206.97 | E35: =SUM(E30:E34) -> 6413.94 | F35: =SUM(F30:F34) -> 6413.94 | G35: =SUM(G30:G34) -> 6413.94 | H35: =SUM(H30:H34) -> 6413.94 | I35: =SUM(I30:I34) -> 6413.94 | J35: =SUM(J30:J34) -> 6413.94 | K35: =SUM(K30:K34) -> 6413.94 | ... Q35: =SUM(Q30:Q34) -> 6413.94
E36: TOTAL EGRESOS FIJOS | F36: =F25+F35+F10 -> 40521.94 | G36: =G25+G35+G10 -> 33521.94 | H36: =H25+H35+H10 -> 33521.94 | I36: =I25+I35+I10 -> 33521.94 | J36: =J25+J35+J10 -> 33521.94 | K36: =K25+K35+K10 -> 33521.94 | L36: =L25+L35+L10 -> 33521.94 | M36: =M25+M35+M10 -> 33521.94 | ... Q36: =Q25+Q35+Q10 -> 33521.94
A39: MEMORIA DE CALCULO GASTOS FIJOS PARA LA INVERSION FIJA | F39: MESES | R39: TOTAL POR 1 SUCURSAL | S39: TOTAL DEL P.I.
A40: CONCEPTO | B40: MEDIDA | C40: CANT | D40: C.U. | E40: TOTAL | F40: 1 | G40: 2 | H40: 3 | I40: 4 | J40: 5 | K40: 6 | L40: 7 | M40: 8 | N40: 9 | O40: 10 | P40: 11 | Q40: 12 | R40: =R10+R20+R22+R23+R21+R24+R30+R31+R32+R33+R34 -> 409263.28 | S40: =S10+S20+S22+S23+S21+S24+S30+S31+S32+S33+S34 -> 3629369.5
A41: Pintura y trabajos de tablaroca | B41: SERVICIO | C41: 1 | D41: 5000 | E41: =C41*D41 -> 5000 | F41: 5000
A42: Equipo de computo | B42: UNIDAD | C42: 1 | D42: 8000 | E42: =C42*D42 -> 8000 | F42: 8000
A43: Modificaciones eléctricas | B43: PZAS | C43: 1 | D43: 1500 | E43: =C43*D43 -> 1500 | F43: 1500
A44: Exhibipaneles | B44: PZAS | C44: 2 | D44: 1000 | E44: =C44*D44 -> 2000 | F44: 2000
A45: Ganchos para exhibipaneles y bases de teléfonos | B45: PZAS | C45: 100 | D45: 15 | E45: =C45*D45 -> 1500 | F45: 1500
A46: Mobiliario (Vitrinas, sillas y caja) | B46: PZAS | C46: 4 | D46: 5000 | E46: =C46*D46 -> 20000 | F46: 20000
A47: Anuncio luminoso | B47: PZAS | C47: 1 | D47: 12000 | E47: =C47*D47 -> 12000 | G47: 12000
A48: Pantalla | B48: PZAS | C48: 1 | D48: 5000 | E48: =C48*D48 -> 5000 | G48: 5000
A49: Depósito de Renta y Renta adelantada del local | B49: UNIDAD | C49: 2 | D49: 6000 | E49: =C49*D49 -> 12000 | F49: 12000
A50: Instalación de Servicios | B50: UNIDAD | C50: 1 | D50: 2000 | E50: =C50*D50 -> 2000 | F50: 2000
A51: Licencia del sistema de Ventas | B51: UNIDAD | C51: 1 | D51: 1000 | E51: =C51*D51 -> 1000 | F51: 1000
A52: Cámaras de seguridad | B52: PZAS | C52: 4 | D52: 1500 | E52: =C52*D52 -> 6000 | H52: 6000
...

Sheet INGRESOS
A2: MEMORIAS DE INGRESOS
A4: PROYECTO: EXPANSIÓN DE MICEL DISTRIBUIDOR AUTORIZADO TELCEL
A5: SOCIEDAD: MICEL DISTRIBUIDOR AUTORIZADO TELCEL- VMD
A6: BENEFICIARIOS: VICTOR DANIEL MARINI DEBERNARDI
A8: CONCEPTOS | B8: INGRESOS POR VENTA MENSUAL AÑO 1
A9: MES | B9: 1 | C9: 2 | D9: 3 | E9: 4 | F9: 5 | G9: 6 | H9: 7 | I9: 8 | J9: 9 | K9: 10 | L9: 11 | M9: 12 | N9: TOTAL
A10: INGRESOS POR PRODUCTOS (telefonía y accesorios)] | B10: 92169.19 | C10: 93090.882 | D10: 94021.791 | E10: 94962.009 | F10: 95911.629 | G10: 96870.745 | H10: 97839.452 | I10: 98817.847 | J10: 99806.025 | K10: 100804.09 | L10: 101812.13 | M10: 102830.25 | N10: ANUAL
A11: INGRESOS POR SERVICIOS | B11: 18195.79 | C11: 18377.748 | D11: 18561.525 | E11: 18747.141 | F11: 18934.612 | G11: 19123.958 | H11: 19315.198 | I11: 19508.35 | J11: 19703.433 | K11: 19900.468 | L11: 20099.472 | M11: 20300.467 | N11: =SUM(B11:M11) -> 230768.16
A12: INGRESOS POR COMISIONES | B12: 300000 | C12: 300000 | D12: 300000 | E12: 300000 | F12: 300000 | G12: 300000 | H12: 300000 | I12: 300000 | J12: 300000 | K12: 300000 | L12: 300000 | M12: 300000 | N12: =+I12 -> 300000
A13: TOTAL DE INGRESOS | B13: =SUM(B10:B12) -> 410364.98 | C13: =SUM(C10:C12) -> 411468.63 | D13: =SUM(D10:D12) -> 412583.32 | E13: =SUM(E10:E12) -> 413709.15 | F13: =SUM(F10:F12) -> 414846.24 | G13: =SUM(G10:G12) -> 415994.7 | H13: =SUM(H10:H12) -> 417154.65 | I13: =SUM(I10:I12) -> 418326.2 | ... M13: =SUM(M10:M12) -> 423130.71 | N13: =SUM(B13:M13) -> 4999704.2
A15: CONCEPTOS | B15: INGRESOS POR VENTA MENSUAL AÑO 2
A16: MES | B16: 1 | C16: 2 | D16: 3 | E16: 4 | F16: 5 | G16: 6 | H16: 7 | I16: 8 | J16: 9 | K16: 10 | L16: 11 | M16: 12 | N16: TOTAL
A17: INGRESOS POR PRODUCTOS (telefonía y accesorios)] | B17: 100464.42 | C17: 100464.42 | D17: 100464.42 | E17: 100464.42 | F17: 100464.42 | G17: 100464.42 | H17: 100464.42 | I17: 100464.42 | J17: 100464.42 | K17: 100464.42 | L17: 100464.42 | M17: 100464.42 | N17: ANUAL
A18: INGRESOS POR SERVICIOS | B18: 19833.411 | C18: 19833.411 | D18: 19833.411 | E18: 19833.411 | F18: 19833.411 | G18: 19833.411 | H18: 19833.411 | I18: 19833.411 | J18: 19833.411 | K18: 19833.411 | L18: 19833.411 | M18: 19833.411 | N18: =+C18+I18 -> 39666.822
A19: INGRESOS POR COMISIONES | B19: 327000 | C19: 327000 | D19: 327000 | E19: 327000 | F19: 327000 | G19: 327000 | H19: 327000 | I19: 327000 | J19: 327000 | K19: 327000 | L19: 327000 | M19: 327000
A20: TOTAL DE INGRESOS | B20: =SUM(B17:B19) -> 447297.83 | C20: =SUM(C17:C19) -> 447297.83 | D20: =SUM(D17:D19) -> 447297.83 | E20: =SUM(E17:E19) -> 447297.83 | F20: =SUM(F17:F19) -> 447297.83 | G20: =SUM(G17:G19) -> 447297.83 | H20: =SUM(H17:H19) -> 447297.83 | I20: =SUM(I17:I19) -> 447297.83 | ... M20: =SUM(M17:M19) -> 447297.83
A22: CONCEPTOS | B22: INGRESOS POR VENTA MENSUAL AÑO 3
A23: MES | B23: 1 | C23: 2 | D23: 3 | E23: 4 | F23: 5 | G23: 6 | H23: 7 | I23: 8 | J23: 9 | K23: 10 | L23: 11 | M23: 12 | N23: TOTAL
A24: INGRESOS POR PRODUCTOS (telefonía y accesorios)] | B24: 109506.21 | C24: 109506.21 | D24: 109506.21 | E24: 109506.21 | F24: 109506.21 | G24: 109506.21 | H24: 109506.21 | I24: 109506.21 | J24: 109506.21 | K24: 109506.21 | L24: 109506.21 | M24: 109506.21 | N24: ANUAL
A25: INGRESOS POR SERVICIOS | B25: 21618.418 | C25: 21618.418 | D25: 21618.418 | E25: 21618.418 | F25: 21618.418 | G25: 21618.418 | H25: 21618.418 | I25: 21618.418 | J25: 21618.418 | K25: 21618.418 | L25: 21618.418 | M25: 21618.418 | N25: =+C24+I24 -> 219012.43
A26: INGRESOS POR COMISIONES | B26: 356430 | C26: 356430 | D26: 356430 | E26: 356430 | F26: 356430 | G26: 356430 | H26: 356430 | I26: 356430 | J26: 356430 | K26: 356430 | L26: 356430 | M26: 356430
A27: TOTAL DE INGRESOS | B27: =SUM(B24:B26) -> 487554.63 | C27: =SUM(C24:C26) -> 487554.63 | D27: =SUM(D24:D26) -> 487554.63 | E27: =SUM(E24:E26) -> 487554.63 | F27: =SUM(F24:F26) -> 487554.63 | G27: =SUM(G24:G26) -> 487554.63 | H27: =SUM(H24:H26) -> 487554.63 | I27: =SUM(I24:I26) -> 487554.63 | ... M27: =SUM(M24:M26) -> 487554.63
A29: CONCEPTOS | B29: INGRESOS POR VENTA MENSUAL AÑO 4
A30: MES | B30: 1 | C30: 2 | D30: 3 | E30: 4 | F30: 5 | G30: 6 | H30: 7 | I30: 8 | J30: 9 | K30: 10 | L30: 11 | M30: 12
A31: INGRESOS POR PRODUCTOS (telefonía y accesorios)] | B31: 119361.77 | C31: 119361.77 | D31: 119361.77 | E31: 119361.77 | F31: 119361.77 | G31: 119361.77 | H31: 119361.77 | I31: 119361.77 | J31: 119361.77 | K31: 119361.77 | L31: 119361.77 | M31: 119361.77 | N31: TOTAL
A32: INGRESOS POR SERVICIOS | B32: 23564.076 | C32: 23564.076 | D32: 23564.076 | E32: 23564.076 | F32: 23564.076 | G32: 23564.076 | H32: 23564.076 | I32: 23564.076 | J32: 23564.076 | K32: 23564.076 | L32: 23564.076 | M32: 23564.076 | N32: ANUAL
A33: INGRESOS POR COMISIONES | B33: 388508.7 | C33: 388508.7 | D33: 388508.7 | E33: 388508.7 | F33: 388508.7 | G33: 388508.7 | H33: 388508.7 | I33: 388508.7 | J33: 388508.7 | K33: 388508.7 | L33: 388508.7 | M33: 388508.7
A34: TOTAL DE INGRESOS | B34: =SUM(B31:B33) -> 531434.55 | C34: =SUM(C31:C33) -> 531434.55 | D34: =SUM(D31:D33) -> 531434.55 | E34: =SUM(E31:E33) -> 531434.55 | F34: =SUM(F31:F33) -> 531434.55 | G34: =SUM(G31:G33) -> 531434.55 | H34: =SUM(H31:H33) -> 531434.55 | I34: =SUM(I31:I33) -> 531434.55 | ... M34: =SUM(M31:M33) -> 531434.55 | N34: =+C34+I34 -> 1062869.1
A37: CONCEPTOS | B37: INGRESOS POR VENTA MENSUAL AÑO 4
A38: MES | B38: 1 | C38: 2 | D38: 3 | E38: 4 | F38: 5 | G38: 6 | H38: 7 | I38: 8 | J38: 9 | K38: 10 | L38: 11 | M38: 12
A39: INGRESOS POR PRODUCTOS (telefonía y accesorios)] | B39: 130104.33 | C39: 130104.33 | D39: 130104.33 | E39: 130104.33 | F39: 130104.33 | G39: 130104.33 | H39: 130104.33 | I39: 130104.33 | J39: 130104.33 | K39: 130104.33 | L39: 130104.33 | M39: 130104.33 | N39: TOTAL
A40: INGRESOS POR SERVICIOS | B40: 25684.843 | C40: 25684.843 | D40: 25684.843 | E40: 25684.843 | F40: 25684.843 | G40: 25684.843 | H40: 25684.843 | I40: 25684.843 | J40: 25684.843 | K40: 25684.843 | L40: 25684.843 | M40: 25684.843 | N40: ANUAL
A41: INGRESOS POR COMISIONES | B41: 423474.48 | C41: 423474.48 | D41: 423474.48 | E41: 423474.48 | F41: 423474.48 | G41: 423474.48 | H41: 423474.48 | I41: 423474.48 | J41: 423474.48 | K41: 423474.48 | L41: 423474.48 | M41: 423474.48
A42: TOTAL DE INGRESOS | B42: =SUM(B39:B41) -> 579263.66 | C42: =SUM(C39:C41) -> 579263.66 | D42: =SUM(D39:D41) -> 579263.66 | E42: =SUM(E39:E41) -> 579263.66 | F42: =SUM(F39:F41) -> 579263.66 | G42: =SUM(G39:G41) -> 579263.66 | H42: =SUM(H39:H41) -> 579263.66 | I42: =SUM(I39:I41) -> 579263.66 | ... M42: =SUM(M39:M41) -> 579263.66 | N42: =+C42+I42 -> 1158527.3

Sheet DEPRECIACIONES
A1: CALCULO DE DEPRECIACIONES Y AMORTIZACIONES
A3: PROYECTO: EXPANSIÓN DE MICEL DISTRIBUIDOR AUTORIZADO TELCEL
A4: SOCIEDAD: MICEL DISTRIBUIDOR AUTORIZADO TELCEL- VMD
A5: BENEFICIARIOS: VICTOR DANIEL MARINI DEBERNARDI
A7: MUEBLES Y EQUIPO | B7: VALOR | C7: VIDA UTIL (AÑOS) | D7: TASA DE DEPREC. | E7: DEPRECIACION (ANUAL) | F7: DEPRECIACION (MENSUAL) | G7: DEPRC. ACUM | H7: REMANENTE
A8: Mobiliario (Vitrinas, sillas y caja) | B8: ='ESTRUCTURA FINANCIERA'!E25 -> 20000 | C8: 10 años | D8: 0.1 | E8: =B8*D8 -> 2000 | F8: =E8/12 -> 166.66667 | G8: =E8*1 -> 2000 | H8: =B8-G8 -> 18000
A9: Exhibipaneles | B9: ='ESTRUCTURA FINANCIERA'!E23 -> 2000 | C9: 10 años | D9: 0.1 | E9: =B9*D9 -> 200 | F9: =E9/12 -> 16.666667 | G9: =E9*1 -> 200 | H9: =B9-G9 -> 1800
A10: Equipo de computo | B10: ='ESTRUCTURA FINANCIERA'!D21 -> 8000 | C10: 3 años | D10: 0.3 | E10: =B10*D10 -> 2400 | F10: =E10/12 -> 200 | G10: =E10*1 -> 2400 | H10: =B10-G10 -> 5600
A11: Anuncio luminoso | B11: ='ESTRUCTURA FINANCIERA'!E26 -> 12000 | C11: 10 años | D11: 0.1 | E11: =B11*D11 -> 1200 | F11: =E11/12 -> 100 | G11: =E11*1 -> 1200 | H11: =B11-G11 -> 10800
A12: Pantalla | B12: ='ESTRUCTURA FINANCIERA'!E27 -> 5000 | C12: 3 años | D12: 0.3 | E12: =B12*D12 -> 1500 | F12: =E12/12 -> 125 | G12: =E12*1 -> 1500 | H12: =B12-G12 -> 3500
A13: Cámaras de seguridad | B13: ='ESTRUCTURA FINANCIERA'!E31 -> 6000 | C13: 10 años | D13: 0.1 | E13: =B13*D13 -> 600 | F13: =E13/12 -> 50 | G13: =E13*1 -> 600 | H13: =B13-G13 -> 5400

Sheet AMORTIZACIONES
A1: AMORTIZACIÓN DE LA DEUDA
A3: PROYECTO:
A4: SOCIEDAD
A5: BENEFICIARIOS:
A6: TABLA DE AMORTIZACION DE LA DEUDA
A8: MESES | B8: TASA DE INTERES | C8: INTERES | D8: DEUDA ACUMULADA | E8: PAGO CAPITAL | F8: PAGO INTERES | G8: PAGO TOTAL | H8: SALDO | I8: FECHAS DE PAGO
A9: 0 | B9: 0
C10: =H9*$B$9 -> 0
C11: =H10*$B$9 -> 0
C12: =H11*$B$9 -> 0
C13: 0
A14: TOTAL | C14: =SUM(C9:C12) -> 0 | E14: 0 | F14: =SUM(F10:F12) -> 0 | G14: 0
A19: PRIMERA MINISTRACIÓN
A20: MONTO: | B20: ='ESTRUCTURA FINANCIERA'!F35 -> 229500 | D20: SOLO NECESITO 1 MINISTRACIÓN PORQUE EN EL PRIMER MES NECESITO TODA LA INVERSIÓN PARA EMPEZAR A OPERAR LA PRIMER SUCURSAL
A21: FECHA: | B21: 46023
A22: SEGUNDA MINISTRACIÓN
A23: MONTO: | B23: =+H9-B20 -> -229500
A24: FECHA:

Sheet COSTOS
B2: COSTOS DE PRODUCCION AÑO 1
A3: VARIABLES | B3: 1 | C3: 2 | D3: 3 | E3: 4 | F3: 5 | G3: 6 | H3: 7 | I3: 8 | J3: 9 | K3: 10 | L3: 11 | M3: 12 | N3: TOTAL
A4: TOTAL VARIABLES | B4: =SUM(B5:B7) -> 215000 | C4: =SUM(C5:C7) -> 215000 | D4: =SUM(D5:D7) -> 215000 | E4: =SUM(E5:E7) -> 215000 | F4: =SUM(F5:F7) -> 215000 | G4: =SUM(G5:G7) -> 215000 | H4: =SUM(H5:H7) -> 215000 | I4: =SUM(I5:I7) -> 215000 | ... N4: =SUM(N5:N7) -> 2580000
A5: TELEFONÍA | B5: 170000 | C5: 170000 | D5: 170000 | E5: 170000 | F5: 170000 | G5: 170000 | H5: 170000 | I5: 170000 | J5: 170000 | K5: 170000 | L5: 170000 | M5: 170000 | N5: =SUM(B5:M5) -> 2040000
A6: ACCESORIOS | B6: 35000 | C6: 35000 | D6: 35000 | E6: 35000 | F6: 35000 | G6: 35000 | H6: 35000 | I6: 35000 | J6: 35000 | K6: 35000 | L6: 35000 | M6: 35000 | N6: =SUM(B6:M6) -> 420000
A7: SALDO EN EL PORTAL | B7: 10000 | C7: 10000 | D7: 10000 | E7: 10000 | F7: 10000 | G7: 10000 | H7: 10000 | I7: 10000 | J7: 10000 | K7: 10000 | L7: 10000 | M7: 10000 | N7: =SUM(B7:M7) -> 120000
A8: TOTAL FIJOS | B8: =SUM(B9:B12) -> 0 | C8: =SUM(C9:C12) -> 0 | D8: =SUM(D9:D12) -> 0 | E8: =SUM(E9:E12) -> 0 | F8: =SUM(F9:F12) -> 0 | G8: =SUM(G9:G12) -> 0 | H8: =SUM(H9:H12) -> 0 | I8: =SUM(I9:I12) -> 0 | ... M8: =SUM(M9:M12) -> 0 | N8: =SUM(B8:M8) -> 0
A13: TOTAL COSTO OPERACIÓN | B13: =+B8+B4 -> 215000 | C13: =+C8+C4 -> 215000 | D13: =+D8+D4 -> 215000 | E13: =+E8+E4 -> 215000 | F13: =+F8+F4 -> 215000 | G13: =+G8+G4 -> 215000 | H13: =+H8+H4 -> 215000 | I13: =+I8+I4 -> 215000 | ... N13: =+N8+N4 -> 2580000
A17: VARIABLES | B17: AÑO 1 | C17: AÑO 2 | D17: AÑO 3 | E17: AÑO 4 | F17: AÑO 5
A18: TOTAL VARIABLES | B18: =SUM(B19:B29) -> 2580000 | C18: =SUM(C19:C29) -> 2580000 | D18: =SUM(D19:D29) -> 2580000 | E18: =SUM(E19:E29) -> 2580000 | F18: =SUM(F19:F29) -> 2580000
A19: TELEFONÍA | B19: 2040000 | C19: 2040000 | D19: 2040000 | E19: 2040000 | F19: 2040000
A20: ACCESORIOS | B20: 420000 | C20: 420000 | D20: 420000 | E20: 420000 | F20: 420000
A21: SALDO EN EL PORTAL | B21: 120000 | C21: 120000 | D21: 120000 | E21: 120000 | F21: 120000
A30: TOTAL FIJOS | B30: =SUM(B31:B45) -> 0 | C30: =SUM(C31:C45) -> 0 | D30: =SUM(D31:D45) -> 0 | E30: =SUM(E31:E45) -> 0 | F30: =SUM(F31:F45) -> 0
A46: TOTAL COSTO OPERACIÓN | B46: =SUM(B30+B18) -> 2580000 | C46: =+C30+C18 -> 2580000 | D46: =SUM(D30+D18) -> 2580000 | E46: =SUM(E30+E18) -> 2580000 | F46: =SUM(F30+F18) -> 2580000

Sheet PROYECCIONES EGRESOS E INGRESOS
A4: 4.9 PUNTO DE EQUILIBRIO
A5: CONCEPTO | B5: AÑO 1 | C5: AÑO 2 | D5: AÑO 3 | E5: AÑO 4 | F5: AÑO 5 | G5: EJEMPLO Y VIDEO FLAVIO
A6: INGRESOS | B6: =INGRESOS!N20
A7: VENTAS
A9: COSTOS DE OPERACION
A10: COSTOS VARIABLES
A11: COSTOS FIJOS
A13: UTILIDAD DE OPERACIÓN
A15: IMPUESTOS
A16: PAGO CAPITAL
A17: UTILIDAD NETA
A19: PUNTO DE EQUILIBRIO
A20: como % de ventas
A24: UTILIDAD POR SOCIO | B24: =+B17/30 -> 0 | C24: =+C17/30 -> 0 | D24: =+D17/30 -> 0 | E24: =+E17/30 -> 0 | F24: =+F17/30 -> 0
A27: GRÁFICA DEL PUNTO DE EQUILIBRIO

Sheet SENSIBILIDAD
A1: SENSIBILIZACION
A3: PROYECTO:
A4: SOCIEDAD
A5: BENEFICIARIOS:
A6: PARA EL PRIMER AÑO
C7: CAMBIO EN VENTAS | G7: CAMBIO EN COSTOS
A8: CONCEPTO | B8: TOTAL PROYECTO | C8: 0.05 | D8: 0.1 | E8: 0.15 | F8: 0.2 | G8: 0.05 | H8: 0.1 | I8: 0.15 | J8: 0.2
A9: VENTAS
A10: COSTOS TOTALES
A11: TOTAL | B11: =SUM(B9-B10) -> 0 | C11: =C9-C10 -> 0 | D11: =D9-D10 -> 0 | E11: =E9-E10 -> 0 | F11: =F9-F10 -> 0 | G11: =G9-G10 -> 0 | H11: =H9-H10 -> 0 | I11: =I9-I10 -> 0 | J11: =J9-J10 -> 0
A13: RELACION B/C | B13: =+B9/B10 -> #DIV/0! | C13: =+C9/C10 -> #DIV/0! | D13: =+D9/D10 -> #DIV/0! | E13: =+E9/E10 -> #DIV/0! | F13: =+F9/F10 -> #DIV/0! | G13: =+G9/G10 -> #DIV/0! | H13: =+H9/H10 -> #DIV/0! | I13: =+I9/I10 -> #DIV/0! | J13: =+J9/J10 -> #DIV/0!
A15: PARA EL SEGUNDO AÑO
C16: CAMBIO EN VENTAS | G16: CAMBIO EN COSTOS
A17: CONCEPTO | B17: TOTAL PROYECTO | C17: 0.05 | D17: 0.1 | E17: 0.15 | F17: 0.2 | G17: 0.05 | H17: 0.1 | I17: 0.15 | J17: 0.2
A18: VENTAS
A19: COSTOS TOTALES
A20: TOTAL | B20: =SUM(B18-B19) -> 0 | C20: =C18-C19 -> 0 | D20: =D18-D19 -> 0 | E20: =E18-E19 -> 0 | F20: =F18-F19 -> 0 | G20: =G18-G19 -> 0 | H20: =H18-H19 -> 0 | I20: =I18-I19 -> 0 | J20: =J18-J19 -> 0
A22: RELACION B/C | B22: =+B18/B19 -> #DIV/0! | C22: =+C18/C19 -> #DIV/0! | D22: =+D18/D19 -> #DIV/0! | E22: =+E18/E19 -> #DIV/0! | F22: =+F18/F19 -> #DIV/0! | G22: =+G18/G19 -> #DIV/0! | H22: =+H18/H19 -> #DIV/0! | I22: =+I18/I19 -> #DIV/0! | J22: =+J18/J19 -> #DIV/0!
A25: PARA EL TERCER AÑO
C26: CAMBIO EN VENTAS | G26: CAMBIO EN COSTOS
A27: CONCEPTO | B27: TOTAL PROYECTO | C27: 0.05 | D27: 0.1 | E27: 0.15 | F27: 0.2 | G27: 0.05 | H27: 0.1 | I27: 0.15 | J27: 0.2
A28: VENTAS
A29: COSTOS TOTALES
A30: TOTAL | B30: =SUM(B28-B29) -> 0 | C30: =C28-C29 -> 0 | D30: =D28-D29 -> 0 | E30: =E28-E29 -> 0 | F30: =F28-F29 -> 0 | G30: =G28-G29 -> 0 | H30: =H28-H29 -> 0 | I30: =I28-I29 -> 0 | J30: =J28-J29 -> 0
A32: RELACION B/C | B32: =+B28/B29 -> #DIV/0! | C32: =+C28/C29 -> #DIV/0! | D32: =+D28/D29 -> #DIV/0! | E32: =+E28/E29 -> #DIV/0! | F32: =+F28/F29 -> #DIV/0! | G32: =+G28/G29 -> #DIV/0! | H32: =+H28/H29 -> #DIV/0! | I32: =+I28/I29 -> #DIV/0! | J32: =+J28/J29 -> #DIV/0!
A36: PARA EL CUARTO AÑO
C37: CAMBIO EN VENTAS | G37: CAMBIO EN COSTOS
A38: CONCEPTO | B38: TOTAL PROYECTO | C38: 0.05 | D38: 0.1 | E38: 0.15 | F38: 0.2 | G38: 0.05 | H38: 0.1 | I38: 0.15 | J38: 0.2
A39: VENTAS
A40: COSTOS TOTALES
A41: TOTAL
A43: RELACION B/C | B43: =+B39/B40 -> #DIV/0! | C43: =+C39/C40 -> #DIV/0! | D43: =+D39/D40 -> #DIV/0! | E43: =+E39/E40 -> #DIV/0! | F43: =+F39/F40 -> #DIV/0! | G43: =+G39/G40 -> #DIV/0! | H43: =+H39/H40 -> #DIV/0! | I43: =+I39/I40 -> #DIV/0! | J43: =+J39/J40 -> #DIV/0!
A47: PARA EL QUINTO AÑO
C48: CAMBIO EN VENTAS | G48: CAMBIO EN COSTOS
A49: CONCEPTO | B49: TOTAL PROYECTO | C49: 0.05 | D49: 0.1 | E49: 0.15 | F49: 0.2 | G49: 0.05 | H49: 0.1 | I49: 0.15 | J49: 0.2
A50: VENTAS
A51: COSTOS TOTALES
A52: TOTAL
A54: RELACION B/C | B54: =+B50/B51 -> #DIV/0! | C54: =+C50/C51 -> #DIV/0! | D54: =+D50/D51 -> #DIV/0! | E54: =+E50/E51 -> #DIV/0! | F54: =+F50/F51 -> #DIV/0! | G54: =+G50/G51 -> #DIV/0! | H54: =+H50/H51 -> #DIV/0! | I54: =+I50/I51 -> #DIV/0! | J54: =+J50/J51 -> #DIV/0!

Sheet TIR - VAN
B2: VAN, TIR Y B/C
C4: TASA DE ACTUALIZACIÓN | E4: 0.09
C6: AÑO | D6: INGRESOS | E6: COSTOS | F6: FLUJO DE EFECTIVO | G6: TASA | H6: INGRESOS | I6: EGRESOS
G7: (1+t)-n | H7: ACTUALIZADOS | I7: ACTUALIZADOS
C8: 0 | D8: 4999704.2 | E8: =215000*12 -> 2580000 | F8: =D8-E8 -> 2419704.2 | G8: =1/(1+$E$4)^C8 -> 1 | H8: =G8*D8 -> 4999704.2 | I8: =G8*E8 -> 2580000
C9: 1 | D9: 5367573.9 | E9: =(215000*1.09)*12 -> 2812200 | F9: =D9-E9 -> 2555373.9 | G9: =1/(1+$E$4)^C9 -> 0.91743119 | H9: =G9*D9 -> 4924379.8 | I9: =G9*E9 -> 2580000 | J9: =H9/I9 -> 1.9086743
C10: 2 | D10: 6377214.6 | E10: =(215000*1.09)*12 -> 2812200 | F10: =D10-E10 -> 3565014.6 | G10: =1/(1+$E$4)^C10 -> 0.84167999 | H10: =G10*D10 -> 5367573.9 | I10: =G10*E10 -> 2366972.5 | J10: =H10/I10 -> 2.267696
C11: 3 | D11: 5850655.6 | E11: =(215000*1.09)*12 -> 2812200 | F11: =D11-E11 -> 3038455.6 | G11: =1/(1+$E$4)^C11 -> 0.77218348 | H11: =G11*D11 -> 4517779.6 | I11: =G11*E11 -> 2171534.4 | J11: =H11/I11 -> 2.080455
C12: 4 | D12: 6377214.6 | E12: =(215000*1.09)*12 -> 2812200 | F12: =D12-E12 -> 3565014.6 | G12: =1/(1+$E$4)^C12 -> 0.70842521 | H12: =G12*D12 -> 4517779.6 | I12: =G12*E12 -> 1992233.4 | J12: =H12/I12 -> 2.267696
C13: 5 | D13: 6951163.9 | E13: =(215000*1.09)*12 -> 2812200 | F13: =D13-E13 -> 4138963.9 | G13: =1/(1+$E$4)^C13 -> 0.64993139 | H13: =G13*D13 -> 4517779.6 | I13: =G13*E13 -> 1827737 | J13: =H13/I13 -> 2.4717886
C14: TOTAL | D14: =SUM(D8:D13) -> 35923527 | H14: =SUM(H8:H13) -> 28844997 | I14: =SUM(I8:I13) -> 13518477
F17: VAN | G17: =H14-I14 -> 15326519
F18: TIR | G18: 0.15
F19: B/C | G19: =H14/I14 -> 2.133746

Sheet BALANCE GENERAL PROFORMA
A3: BALANCE GENERAL PROFORMA
A4: CONCEPTO FIJO | B4: AÑO 1 | C4: AÑO 2 | D4: AÑO 3 | E4: AÑO 4
A5: ACTIVO CIRCULANTE
A7: Total activo circulante | B7: =+'CUADRO DE EGRESOS E INGRESOS'!B94 -> 2010440.9 | C7: =+C6 | D7: =+D6 | E7: =+E6
A9: ACTIVO FIJO
A32: TOTAL DE ACTIVO FIJO | B32: =+DEPRECIACIONES!#REF! -> #ERROR! | C32: =+B32/10+B32 -> #ERROR! | D32: =+B32/10+C32 -> #ERROR! | E32: =+B32/10+D32 -> #ERROR!
B33: =SUM(B10:B32) -> #ERROR! | C33: =SUM(C10:C32) -> #ERROR! | D33: =SUM(D10:D32) -> #ERROR! | E33: =SUM(E10:E32) -> #ERROR!
A34: PASIVO
A36: TOTAL PASIVO
A37: CAPITAL CONTABLE

Sheet ESTADO DE RESULTADOS
B2: 1 de enero al 31 de diciembre de 2024
B3: ESTADO DE RESULTADOS MICEL DISTRIBUIDOR AUTORIZADO TELCEL
B4: Ventas | C4: 24105840 | D4: 1
B5: Comisiones | C5: 4320000 | D5: 0.1792
B6: Costo de ventas | C6: 21695256 | D6: 0.9
B7: Utilidad bruta | C7: 6730584 | D7: 0.2792
B8: Gastos de operación | C8: 1008000 | D8: 0.0418
B9: Gastos administrativos | C9: 2691000 | D9: 0.1116
B10: Gastos de venta | C10: 12000 | D10: 0.0005
B11: Utilidad de operación | C11: 3019584 | D11: 0.1253
B12: utilidad antes de impuestos | C12: 3019584 | D12: 0.1253
B13: ISR | C13: 905875.2 | D13: 0.0376
B14: utilidad neta | C14: 2113708.8 | D14: 0.0877

Sheet CRONOGRAMA DE ACTIVIDADES
A1: CRONOGRAMA DE ACTIVIDADES
A3: PROYECTO:
A4: SOCIEDAD
A5: BENEFICIARIOS:
A7: CRONOGRAMA DE ACTIVIDADES
C8: MES
A9: CONCEPTO | C9: 1 | D9: 2 | E9: 3 | F9: 4 | G9: 5 | H9: 6 | I9: 7 | J9: 8 | K9: 9 | L9: 10 | M9: 11 | N9: 12
A51: CRONOGRAMA DE ACTIVIDADES SEGUNDO AÑO
B53: CONCEPTO | C53: 1 | D53: 2 | E53: 3 | F53: 4 | G53: 5 | H53: 6 | I53: 7 | J53: 8 | K53: 9 | L53: 10 | M53: 11 | N53: 12
A68: CRONOGRAMA DE ACTIVIDADES TERCER AÑO
B70: CONCEPTO | C70: 1 | D70: 2 | E70: 3 | F70: 4 | G70: 5 | H70: 6 | I70: 7 | J70: 8 | K70: 9 | L70: 10 | M70: 11 | N70: 12
A85: CRONOGRAMA DE ACTIVIDADES CUARTO AÑO
B87: CONCEPTO | C87: 1 | D87: 2 | E87: 3 | F87: 4 | G87: 5 | H87: 6 | I87: 7 | J87: 8 | K87: 9 | L87: 10 | M87: 11 | N87: 12
